Workbook

Sheet 01_סיכום_האירוע
A1: סיכום האירוע | B1: ערך | C1: הערה
A2: שם האירוע | B2: חתונת QA | C2: פרטי האירוע
A3: לקוח / משפחה | B3: משפחת כהן-לוי | C3: פרטי לקוח
A4: תאריך | B4: 2026-07-18 | C4: פרטי האירוע
A5: מקום | B5: גן עדן אירועים | C5: פרטי האירוע
A6: סה״כ מוזמנים | B6: =COUNTIF('02_Guest_Database'!B2:B999,"<>") | C6: מתעדכן מרשימת האורחים
A7: מאשרים הגעה | B7: =COUNTIF('02_Guest_Database'!C2:C999,"מאשר הגעה") | C7: סטטוס אורחים
A8: ממתינים לאישור | B8: =COUNTIF('02_Guest_Database'!C2:C999,"טרם השיב") | C8: דורש מעקב
A9: לא מגיעים | B9: =COUNTIF('02_Guest_Database'!C2:C999,"לא מגיע") | C9: סטטוס אורחים
A10: מספר שולחנות | B10: =COUNTIF('05_Seating'!A14:A999,">0") | C10: לפי טבלת ההושבה
A11: קיבולת כוללת | B11: ='05_Seating'!B4 | C11: סך מושבים שהוגדרו
A12: אורחים מאשרים ללא שולחן | B12: ='05_Seating'!B3 | C12: דורש החלטת הושבה
A13: אורחים משובצים | B13: ='05_Seating'!B2 | C13: לפי שיוך אורחים
A14: פער קיבולת | B14: =B11-B7 | C14: חיובי = עודף מושבים; שלילי = חסר
A15: תפוסת הושבה | B15: ='05_Seating'!B6 | C15: לפי שולחנות שהוגדרו
A16: שולחנות בחריגה | B16: ='05_Seating'!B8 | C16: דורש בדיקה
A17: קבוצות שפוצלו | B17: 1 | C17: לפי המלצות הושבה אחרונות
A18: סה״כ ספקים | B18: =COUNTIF('07_Suppliers'!B11:B999,"<>") | C18: מתעדכן מרשימת הספקים
A19: תקציב מתוכנן | B19: ='08_Budget'!B2 | C19: ספקים וסעיפי תקציב
A20: שולם | B20: ='08_Budget'!B3 | C20: ספקים
A21: יתרה לתשלום | B21: ='08_Budget'!B8 | C21: דורש מעקב
A22: עלות לאורח | B22: =IFERROR(B19/B6,0) | C22: מדד תכנון
A23: נושאים לטיפול | B23: =COUNTIF('10_Risks'!E2:E999,"פעיל") | C23: דורש תשומת לב
A24: מקור אמת | B24: רשומת האירוע והחוברת הם בסיס העבודה התפעולי. האפליקציה היא סביבת עבודה ויזואלית. | C24: החלטות ידניות של מנהל האירוע
A26: קישורים משניים לאפליקציה | B26: פתיחה באותו מכשיר/דפדפן שבו האירוע נשמר | C26: ניווט בלבד
A27: סקירה | B27: פתח סקירה | C27: אפליקציה
A28: אורחים | B28: פתח אורחים | C28: אפליקציה
A29: הושבה | B29: פתח הושבה | C29: אפליקציה
A30: ספקים | B30: פתח ספקים | C30: אפליקציה
A31: סיכונים | B31: פתח סיכונים | C31: אפליקציה

Sheet 02_Guest_Database
A1: מזהה | B1: שם אורח | C1: סטטוס הגעה | D1: קטגוריה | E1: תזונה | F1: שולחן | G1: הערות | H1: יש שולחן | I1: רב-קטגוריה | J1: מחבר חברתי | L1: ניווט לאפליקציה | M1: האקסל הוא ספר התכנון. הקישור פותח את תצוגת האורחים באפליקציה.
A2: G-0001 | B2: לקוח: משפחת כהן-לוי | C2: טרם השיב | D2: משפחה | E2: ללא | H2: =IF(OR(F2="",F2=0),"לא","כן") | I2: =IF(ISNUMBER(SEARCH(",",D2)),"כן","לא") | J2: =IF(OR(ISNUMBER(SEARCH(",",D2)),ISNUMBER(SEARCH("קבוצות",G2))),"כן","לא") | L2: פתח את תצוגת האורחים | M2: פתח את תצוגת האורחים
A3: G-0002 | B3: מולר | C3: מאשר הגעה | D3: חבר גרעין | E3: ללא | F3: 1 | H3: =IF(OR(F3="",F3=0),"לא","כן") | I3: =IF(ISNUMBER(SEARCH(",",D3)),"כן","לא") | J3: =IF(OR(ISNUMBER(SEARCH(",",D3)),ISNUMBER(SEARCH("קבוצות",G3))),"כן","לא")
A4: G-0003 | B4: מידן | C4: מאשר הגעה | D4: חבר גרעין | E4: ללא | F4: 1 | H4: =IF(OR(F4="",F4=0),"לא","כן") | I4: =IF(ISNUMBER(SEARCH(",",D4)),"כן","לא") | J4: =IF(OR(ISNUMBER(SEARCH(",",D4)),ISNUMBER(SEARCH("קבוצות",G4))),"כן","לא")
A5: G-0004 | B5: תואם | C5: מאשר הגעה | D5: חבר גרעין, לימודים | E5: ללא | F5: 3 | G5: קבוצות: חבר גרעין, לימודים | H5: =IF(OR(F5="",F5=0),"לא","כן") | I5: =IF(ISNUMBER(SEARCH(",",D5)),"כן","לא") | J5: =IF(OR(ISNUMBER(SEARCH(",",D5)),ISNUMBER(SEARCH("קבוצות",G5))),"כן","לא")
A6: G-0005 | B6: זוהר | C6: מאשר הגעה | D6: לימודים | E6: ללא | F6: 2 | H6: =IF(OR(F6="",F6=0),"לא","כן") | I6: =IF(ISNUMBER(SEARCH(",",D6)),"כן","לא") | J6: =IF(OR(ISNUMBER(SEARCH(",",D6)),ISNUMBER(SEARCH("קבוצות",G6))),"כן","לא")
A7: G-0006 | B7: פלג | C7: מאשר הגעה | D7: לימודים | E7: ללא | F7: 2 | H7: =IF(OR(F7="",F7=0),"לא","כן") | I7: =IF(ISNUMBER(SEARCH(",",D7)),"כן","לא") | J7: =IF(OR(ISNUMBER(SEARCH(",",D7)),ISNUMBER(SEARCH("קבוצות",G7))),"כן","לא")
A8: G-0007 | B8: נועה כהן | C8: מאשר הגעה | D8: משפחה | E8: טבעוני | F8: 1 | G8: צד: צד הכלה | H8: =IF(OR(F8="",F8=0),"לא","כן") | I8: =IF(ISNUMBER(SEARCH(",",D8)),"כן","לא") | J8: =IF(OR(ISNUMBER(SEARCH(",",D8)),ISNUMBER(SEARCH("קבוצות",G8))),"כן","לא")
A9: G-0008 | B9: דניאל לוי | C9: מאשר הגעה | D9: משפחה, VIP | E9: ללא | F9: 3 | G9: צד: צד החתן | H9: =IF(OR(F9="",F9=0),"לא","כן") | I9: =IF(ISNUMBER(SEARCH(",",D9)),"כן","לא") | J9: =IF(OR(ISNUMBER(SEARCH(",",D9)),ISNUMBER(SEARCH("קבוצות",G9))),"כן","לא")
H10: =IF(OR(F10="",F10=0),"לא","כן") | I10: =IF(ISNUMBER(SEARCH(",",D10)),"כן","לא") | J10: =IF(OR(ISNUMBER(SEARCH(",",D10)),ISNUMBER(SEARCH("קבוצות",G10))),"כן","לא")
H11: =IF(OR(F11="",F11=0),"לא","כן") | I11: =IF(ISNUMBER(SEARCH(",",D11)),"כן","לא") | J11: =IF(OR(ISNUMBER(SEARCH(",",D11)),ISNUMBER(SEARCH("קבוצות",G11))),"כן","לא")
H12: =IF(OR(F12="",F12=0),"לא","כן") | I12: =IF(ISNUMBER(SEARCH(",",D12)),"כן","לא") | J12: =IF(OR(ISNUMBER(SEARCH(",",D12)),ISNUMBER(SEARCH("קבוצות",G12))),"כן","לא")
H13: =IF(OR(F13="",F13=0),"לא","כן") | I13: =IF(ISNUMBER(SEARCH(",",D13)),"כן","לא") | J13: =IF(OR(ISNUMBER(SEARCH(",",D13)),ISNUMBER(SEARCH("קבוצות",G13))),"כן","לא")
H14: =IF(OR(F14="",F14=0),"לא","כן") | I14: =IF(ISNUMBER(SEARCH(",",D14)),"כן","לא") | J14: =IF(OR(ISNUMBER(SEARCH(",",D14)),ISNUMBER(SEARCH("קבוצות",G14))),"כן","לא")
H15: =IF(OR(F15="",F15=0),"לא","כן") | I15: =IF(ISNUMBER(SEARCH(",",D15)),"כן","לא") | J15: =IF(OR(ISNUMBER(SEARCH(",",D15)),ISNUMBER(SEARCH("קבוצות",G15))),"כן","לא")
H16: =IF(OR(F16="",F16=0),"לא","כן") | I16: =IF(ISNUMBER(SEARCH(",",D16)),"כן","לא") | J16: =IF(OR(ISNUMBER(SEARCH(",",D16)),ISNUMBER(SEARCH("קבוצות",G16))),"כן","לא")
H17: =IF(OR(F17="",F17=0),"לא","כן") | I17: =IF(ISNUMBER(SEARCH(",",D17)),"כן","לא") | J17: =IF(OR(ISNUMBER(SEARCH(",",D17)),ISNUMBER(SEARCH("קבוצות",G17))),"כן","לא")
H18: =IF(OR(F18="",F18=0),"לא","כן") | I18: =IF(ISNUMBER(SEARCH(",",D18)),"כן","לא") | J18: =IF(OR(ISNUMBER(SEARCH(",",D18)),ISNUMBER(SEARCH("קבוצות",G18))),"כן","לא")
H19: =IF(OR(F19="",F19=0),"לא","כן") | I19: =IF(ISNUMBER(SEARCH(",",D19)),"כן","לא") | J19: =IF(OR(ISNUMBER(SEARCH(",",D19)),ISNUMBER(SEARCH("קבוצות",G19))),"כן","לא")
H20: =IF(OR(F20="",F20=0),"לא","כן") | I20: =IF(ISNUMBER(SEARCH(",",D20)),"כן","לא") | J20: =IF(OR(ISNUMBER(SEARCH(",",D20)),ISNUMBER(SEARCH("קבוצות",G20))),"כן","לא")
H21: =IF(OR(F21="",F21=0),"לא","כן") | I21: =IF(ISNUMBER(SEARCH(",",D21)),"כן","לא") | J21: =IF(OR(ISNUMBER(SEARCH(",",D21)),ISNUMBER(SEARCH("קבוצות",G21))),"כן","לא")
... H999: =IF(OR(F999="",F999=0),"לא","כן") | I999: =IF(ISNUMBER(SEARCH(",",D999)),"כן","לא") | J999: =IF(OR(ISNUMBER(SEARCH(",",D999)),ISNUMBER(SEARCH("קבוצות",G999))),"כן","לא")

Sheet 03_RSVP_Status
A1: סטטוס | B1: כמות | C1: אחוז
A2: מאשר הגעה | B2: =COUNTIF('02_Guest_Database'!C2:C999,"מאשר הגעה") | C2: =IFERROR(B2/SUM(B2:B4),0)
A3: טרם השיב | B3: =COUNTIF('02_Guest_Database'!C2:C999,"טרם השיב") | C3: =IFERROR(B3/SUM(B2:B4),0)
A4: לא מגיע | B4: =COUNTIF('02_Guest_Database'!C2:C999,"לא מגיע") | C4: =IFERROR(B4/SUM(B2:B4),0)
A5: הערה | B5: אין כאן מערכת RSVP. זהו סיכום תפעולי לעבודה ידנית.

Sheet 04_Categories
A1: מדד | B1: ערך | C1: הערה
A2: סה״כ קטגוריות | B2: =COUNTIF(A15:A999,"<>") | C2: מתעדכן מרשימת האורחים
A3: קטגוריה גדולה ביותר | B3: =IFERROR(INDEX(A15:A999,MATCH(MAX(B15:B999),B15:B999,0)),"") | C3: מתעדכן מרשימת האורחים
A4: גודל קטגוריה מובילה | B4: =IFERROR(MAX(B15:B999),0) | C4: מתעדכן מרשימת האורחים
A5: אורחי VIP | B5: =COUNTIF('02_Guest_Database'!D2:D999,"*VIP*") | C5: מתעדכן מרשימת האורחים
A6: אורחים עם מגבלת תזונה | B6: =COUNTIFS('02_Guest_Database'!E2:E999,"<>",'02_Guest_Database'!E2:E999,"<>ללא") | C6: מתעדכן מרשימת האורחים
A7: אורחים רב-קטגוריה | B7: =COUNTIF('02_Guest_Database'!I2:I999,"כן") | C7: מתעדכן מרשימת האורחים
A8: מחברים חברתיים | B8: =COUNTIF('02_Guest_Database'!J2:J999,"כן") | C8: מתעדכן מרשימת האורחים
A10: סיכום תזונה | B10: כמות
A11: טבעוני | B11: =COUNTIF('02_Guest_Database'!E2:E999,"*טבעוני*")
A12: ללא גלוטן | B12: =COUNTIF('02_Guest_Database'!E2:E999,"*גלוטן*")
A13: אלרגיה | B13: =COUNTIF('02_Guest_Database'!E2:E999,"*אלרג*")
A14: קטגוריה | B14: כמות אורחים | C14: הערה
A15: משפחה | B15: =COUNTIF('02_Guest_Database'!D2:D999,"*משפחה*") | C15: מתעדכן אוטומטית
A16: חבר גרעין | B16: =COUNTIF('02_Guest_Database'!D2:D999,"*חבר גרעין*") | C16: מתעדכן אוטומטית
A17: לימודים | B17: =COUNTIF('02_Guest_Database'!D2:D999,"*לימודים*") | C17: מתעדכן אוטומטית
A18: VIP | B18: =COUNTIF('02_Guest_Database'!D2:D999,"*VIP*") | C18: מתעדכן אוטומטית

Sheet 05_Seating
A1: מדד | B1: ערך | C1: הערה | L1: סקיצת הושבה ויזואלית | M1: האקסל הוא מקור האמת התפעולי. הקישור פותח את תצוגת ההושבה הוויזואלית באפליקציה.
A2: אורחים משובצים | B2: =COUNTIF('02_Guest_Database'!F2:F999,">0") | C2: מתעדכן מרשימת האורחים | L2: פתח את מסך ההושבה | M2: פתח את מסך ההושבה
A3: אורחים מאשרים ללא שולחן | B3: =COUNTIFS('02_Guest_Database'!B2:B999,"<>",'02_Guest_Database'!C2:C999,"מאשר הגעה",'02_Guest_Database'!F2:F999,"")+COUNTIFS('02_Guest_Database'!B2:B999,"<>",'02_Guest_Database'!C2:C999,"מאשר הגעה",'02_Guest_Database'!F2:F999,0) | C3: דורש החלטת הושבה
A4: סה״כ מושבים | B4: =SUM(D14:D999) | C4: לפי שולחנות שהוגדרו
A5: מושבים תפוסים | B5: =SUM(E14:E999) | C5: לפי שיוך אורחים
A6: אחוז תפוסה | B6: =IFERROR(B5/B4,0) | C6: מצב הושבה
A7: מושבים פנויים | B7: =SUM(F14:F999) | C7: לפי שולחנות שהוגדרו
A8: אזהרות קיבולת | B8: =SUMPRODUCT(--(H14:H999<>""),--(H14:H999<>"תקין")) | C8: דורש בדיקה
A10: סקיצת הושבה ויזואלית | B10: האקסל הוא מקור האמת התפעולי. הקישור פותח את תצוגת ההושבה הוויזואלית באפליקציה. | C10: ניווט בלבד
A11: פתח את מסך ההושבה | C11: אפליקציה
A13: שולחן | B13: כינוי | C13: קטגוריה | D13: קיבולת | E13: אורחים משובצים | F13: מקומות פנויים | G13: תפוסה | H13: אזהרת קיבולת | I13: תמהיל קטגוריות | J13: סוג | K13: אזור | L13: הערות והמלצות
A14: 1 | B14: שולחן 1 | C14: משפחה | D14: 10 | E14: =IF(A14="","",COUNTIF('02_Guest_Database'!F2:F999,A14)) | F14: =IF(A14="","",MAX(0,D14-E14)) | G14: =IF(A14="","",IFERROR(E14/D14,0)) | H14: =IF(A14="","",IF(E14>D14,"חריגת קיבולת",IF(E14=D14,"מלא","תקין"))) | I14: חבר גרעין: 2 | משפחה: 1 | L14: נוצר לפי שיוך אורחים שהוזן מומלץ להושיב את קבוצת 'חבר גרעין' בשולחן 1 — הקבוצה נכנסת במלואה. מומלץ להושיב את קבוצת 'משפחה' בשולחן 1 — הקבוצה נכנסת במלואה.
A15: 2 | B15: שולחן 2 | C15: משפחה | D15: 10 | E15: =IF(A15="","",COUNTIF('02_Guest_Database'!F2:F999,A15)) | F15: =IF(A15="","",MAX(0,D15-E15)) | G15: =IF(A15="","",IFERROR(E15/D15,0)) | H15: =IF(A15="","",IF(E15>D15,"חריגת קיבולת",IF(E15=D15,"מלא","תקין"))) | I15: לימודים: 2 | L15: נוצר לפי שיוך אורחים שהוזן מומלץ להושיב את קבוצת 'לימודים' בשולחן 2 — הקבוצה נכנסת במלואה.
A16: 3 | B16: שולחן 3 | C16: חברים | D16: 10 | E16: =IF(A16="","",COUNTIF('02_Guest_Database'!F2:F999,A16)) | F16: =IF(A16="","",MAX(0,D16-E16)) | G16: =IF(A16="","",IFERROR(E16/D16,0)) | H16: =IF(A16="","",IF(E16>D16,"חריגת קיבולת",IF(E16=D16,"מלא","תקין"))) | I16: חבר גרעין, לימודים: 1 | משפחה, VIP: 1 | L16: נוסף בבדיקת QA מומלץ להושיב את קבוצת 'חבר גרעין, לימודים' בשולחן 3 — הקבוצה נכנסת במלואה. קבוצת 'משפחה, VIP' כוללת 1 אורחים ולכן מומלץ לפצל בין שולחן 3.
B17: המלצות הושבה | E17: =IF(A17="","",COUNTIF('02_Guest_Database'!F2:F999,A17)) | F17: =IF(A17="","",MAX(0,D17-E17)) | G17: =IF(A17="","",IFERROR(E17/D17,0)) | H17: =IF(A17="","",IF(E17>D17,"חריגת קיבולת",IF(E17=D17,"מלא","תקין"))) | L17: מומלץ להושיב את קבוצת 'חבר גרעין' בשולחן 1 — הקבוצה נכנסת במלואה. מומלץ להושיב את קבוצת 'לימודים' בשולחן 2 — הקבוצה נכנסת במלואה. מומלץ להושיב את קבוצת 'חבר גרעין, לימודים' בשולחן 3 — הקבוצה נכנסת במלואה. מומלץ להושיב את קבוצת 'משפחה' בשולחן 1 — הקבוצה נכנסת במלואה. קבוצת 'משפחה, VIP' כוללת 1 אורחים ולכן מומלץ לפצל בין שולחן 3. טרם השיבו — לא שובצו: לקוח: משפחת כהן-לוי המלצה בלבד — מנהל האירוע מחליט.
E18: =IF(A18="","",COUNTIF('02_Guest_Database'!F2:F999,A18)) | F18: =IF(A18="","",MAX(0,D18-E18)) | G18: =IF(A18="","",IFERROR(E18/D18,0)) | H18: =IF(A18="","",IF(E18>D18,"חריגת קיבולת",IF(E18=D18,"מלא","תקין")))
E19: =IF(A19="","",COUNTIF('02_Guest_Database'!F2:F999,A19)) | F19: =IF(A19="","",MAX(0,D19-E19)) | G19: =IF(A19="","",IFERROR(E19/D19,0)) | H19: =IF(A19="","",IF(E19>D19,"חריגת קיבולת",IF(E19=D19,"מלא","תקין")))
E20: =IF(A20="","",COUNTIF('02_Guest_Database'!F2:F999,A20)) | F20: =IF(A20="","",MAX(0,D20-E20)) | G20: =IF(A20="","",IFERROR(E20/D20,0)) | H20: =IF(A20="","",IF(E20>D20,"חריגת קיבולת",IF(E20=D20,"מלא","תקין")))
E21: =IF(A21="","",COUNTIF('02_Guest_Database'!F2:F999,A21)) | F21: =IF(A21="","",MAX(0,D21-E21)) | G21: =IF(A21="","",IFERROR(E21/D21,0)) | H21: =IF(A21="","",IF(E21>D21,"חריגת קיבולת",IF(E21=D21,"מלא","תקין")))
E22: =IF(A22="","",COUNTIF('02_Guest_Database'!F2:F999,A22)) | F22: =IF(A22="","",MAX(0,D22-E22)) | G22: =IF(A22="","",IFERROR(E22/D22,0)) | H22: =IF(A22="","",IF(E22>D22,"חריגת קיבולת",IF(E22=D22,"מלא","תקין")))
E23: =IF(A23="","",COUNTIF('02_Guest_Database'!F2:F999,A23)) | F23: =IF(A23="","",MAX(0,D23-E23)) | G23: =IF(A23="","",IFERROR(E23/D23,0)) | H23: =IF(A23="","",IF(E23>D23,"חריגת קיבולת",IF(E23=D23,"מלא","תקין")))
E24: =IF(A24="","",COUNTIF('02_Guest_Database'!F2:F999,A24)) | F24: =IF(A24="","",MAX(0,D24-E24)) | G24: =IF(A24="","",IFERROR(E24/D24,0)) | H24: =IF(A24="","",IF(E24>D24,"חריגת קיבולת",IF(E24=D24,"מלא","תקין")))
E25: =IF(A25="","",COUNTIF('02_Guest_Database'!F2:F999,A25)) | F25: =IF(A25="","",MAX(0,D25-E25)) | G25: =IF(A25="","",IFERROR(E25/D25,0)) | H25: =IF(A25="","",IF(E25>D25,"חריגת קיבולת",IF(E25=D25,"מלא","תקין")))
E26: =IF(A26="","",COUNTIF('02_Guest_Database'!F2:F999,A26)) | F26: =IF(A26="","",MAX(0,D26-E26)) | G26: =IF(A26="","",IFERROR(E26/D26,0)) | H26: =IF(A26="","",IF(E26>D26,"חריגת קיבולת",IF(E26=D26,"מלא","תקין")))
E27: =IF(A27="","",COUNTIF('02_Guest_Database'!F2:F999,A27)) | F27: =IF(A27="","",MAX(0,D27-E27)) | G27: =IF(A27="","",IFERROR(E27/D27,0)) | H27: =IF(A27="","",IF(E27>D27,"חריגת קיבולת",IF(E27=D27,"מלא","תקין")))
E28: =IF(A28="","",COUNTIF('02_Guest_Database'!F2:F999,A28)) | F28: =IF(A28="","",MAX(0,D28-E28)) | G28: =IF(A28="","",IFERROR(E28/D28,0)) | H28: =IF(A28="","",IF(E28>D28,"חריגת קיבולת",IF(E28=D28,"מלא","תקין")))
E29: =IF(A29="","",COUNTIF('02_Guest_Database'!F2:F999,A29)) | F29: =IF(A29="","",MAX(0,D29-E29)) | G29: =IF(A29="","",IFERROR(E29/D29,0)) | H29: =IF(A29="","",IF(E29>D29,"חריגת קיבולת",IF(E29=D29,"מלא","תקין")))
E30: =IF(A30="","",COUNTIF('02_Guest_Database'!F2:F999,A30)) | F30: =IF(A30="","",MAX(0,D30-E30)) | G30: =IF(A30="","",IFERROR(E30/D30,0)) | H30: =IF(A30="","",IF(E30>D30,"חריגת קיבולת",IF(E30=D30,"מלא","תקין")))
E31: =IF(A31="","",COUNTIF('02_Guest_Database'!F2:F999,A31)) | F31: =IF(A31="","",MAX(0,D31-E31)) | G31: =IF(A31="","",IFERROR(E31/D31,0)) | H31: =IF(A31="","",IF(E31>D31,"חריגת קיבולת",IF(E31=D31,"מלא","תקין")))
E32: =IF(A32="","",COUNTIF('02_Guest_Database'!F2:F999,A32)) | F32: =IF(A32="","",MAX(0,D32-E32)) | G32: =IF(A32="","",IFERROR(E32/D32,0)) | H32: =IF(A32="","",IF(E32>D32,"חריגת קיבולת",IF(E32=D32,"מלא","תקין")))
E33: =IF(A33="","",COUNTIF('02_Guest_Database'!F2:F999,A33)) | F33: =IF(A33="","",MAX(0,D33-E33)) | G33: =IF(A33="","",IFERROR(E33/D33,0)) | H33: =IF(A33="","",IF(E33>D33,"חריגת קיבולת",IF(E33=D33,"מלא","תקין")))
E34: =IF(A34="","",COUNTIF('02_Guest_Database'!F2:F999,A34)) | F34: =IF(A34="","",MAX(0,D34-E34)) | G34: =IF(A34="","",IFERROR(E34/D34,0)) | H34: =IF(A34="","",IF(E34>D34,"חריגת קיבולת",IF(E34=D34,"מלא","תקין")))
E35: =IF(A35="","",COUNTIF('02_Guest_Database'!F2:F999,A35)) | F35: =IF(A35="","",MAX(0,D35-E35)) | G35: =IF(A35="","",IFERROR(E35/D35,0)) | H35: =IF(A35="","",IF(E35>D35,"חריגת קיבולת",IF(E35=D35,"מלא","תקין")))
E36: =IF(A36="","",COUNTIF('02_Guest_Database'!F2:F999,A36)) | F36: =IF(A36="","",MAX(0,D36-E36)) | G36: =IF(A36="","",IFERROR(E36/D36,0)) | H36: =IF(A36="","",IF(E36>D36,"חריגת קיבולת",IF(E36=D36,"מלא","תקין")))
E37: =IF(A37="","",COUNTIF('02_Guest_Database'!F2:F999,A37)) | F37: =IF(A37="","",MAX(0,D37-E37)) | G37: =IF(A37="","",IFERROR(E37/D37,0)) | H37: =IF(A37="","",IF(E37>D37,"חריגת קיבולת",IF(E37=D37,"מלא","תקין")))
E38: =IF(A38="","",COUNTIF('02_Guest_Database'!F2:F999,A38)) | F38: =IF(A38="","",MAX(0,D38-E38)) | G38: =IF(A38="","",IFERROR(E38/D38,0)) | H38: =IF(A38="","",IF(E38>D38,"חריגת קיבולת",IF(E38=D38,"מלא","תקין")))
E39: =IF(A39="","",COUNTIF('02_Guest_Database'!F2:F999,A39)) | F39: =IF(A39="","",MAX(0,D39-E39)) | G39: =IF(A39="","",IFERROR(E39/D39,0)) | H39: =IF(A39="","",IF(E39>D39,"חריגת קיבולת",IF(E39=D39,"מלא","תקין")))
E40: =IF(A40="","",COUNTIF('02_Guest_Database'!F2:F999,A40)) | F40: =IF(A40="","",MAX(0,D40-E40)) | G40: =IF(A40="","",IFERROR(E40/D40,0)) | H40: =IF(A40="","",IF(E40>D40,"חריגת קיבולת",IF(E40=D40,"מלא","תקין")))
E41: =IF(A41="","",COUNTIF('02_Guest_Database'!F2:F999,A41)) | F41: =IF(A41="","",MAX(0,D41-E41)) | G41: =IF(A41="","",IFERROR(E41/D41,0)) | H41: =IF(A41="","",IF(E41>D41,"חריגת קיבולת",IF(E41=D41,"מלא","תקין")))
E42: =IF(A42="","",COUNTIF('02_Guest_Database'!F2:F999,A42)) | F42: =IF(A42="","",MAX(0,D42-E42)) | G42: =IF(A42="","",IFERROR(E42/D42,0)) | H42: =IF(A42="","",IF(E42>D42,"חריגת קיבולת",IF(E42=D42,"מלא","תקין")))
...

Sheet 06_Venue
A1: נתון אולם | B1: ערך
A2: מקום האירוע | B2: גן עדן אירועים
A3: תאריך | B3: 2026-07-18
A4: כמות אורחים משוערת | B4: 250
A5: מספר שולחנות שהוגדרו | B5: 3
A6: הערות | B6: אין נתוני אולם שהומצאו אוטומטית. יש לעדכן ידנית לפי המקום.

Sheet 07_Suppliers
A1: מדד | B1: ערך | C1: הערה | L1: ניווט לאפליקציה | M1: האקסל הוא ספר התכנון. הקישור פותח את תצוגת הספקים באפליקציה.
A2: סה״כ ספקים | B2: =COUNTIF(B11:B999,"<>") | C2: מתעדכן מרשימת הספקים | L2: פתח את תצוגת הספקים | M2: פתח את תצוגת הספקים
A3: חסר טלפון | B3: =SUMPRODUCT(--(B11:B999<>""),--(C11:C999="")) | C3: דורש השלמה
A4: חסר עלות | B4: =SUMPRODUCT(--(B11:B999<>""),--(D11:D999=0)) | C4: דורש השלמה
A5: ספקים לא משולמים | B5: =SUMPRODUCT(--(B11:B999<>""),--(F11:F999>0)) | C5: דורש מעקב תשלום
A6: עלות ספקים כוללת | B6: =SUM(D11:D999) | C6: מתעדכן מרשימת הספקים
A7: שולם לספקים | B7: =SUM(E11:E999) | C7: מצב תשלום
A8: יתרה לספקים | B8: =SUM(F11:F999) | C8: מצב תשלום
A10: תחום | B10: שם ספק | C10: טלפון | D10: עלות חוזה | E10: שולם | F10: יתרה | G10: סטטוס | H10: חסר טלפון | I10: חסר עלות | J10: לא שולם
A11: קייטרינג ובר | B11: קייטרינג טעם טוב - - מקדמה - - | C11: 050-8887766 | D11: 42000 | E11: 12000 | F11: =IF(B11="","",MAX(0,D11-E11)) | G11: שולם חלקית | H11: =IF(B11="","",IF(C11="","כן","לא")) | I11: =IF(B11="","",IF(D11=0,"כן","לא")) | J11: =IF(B11="","",IF(F11>0,"כן","לא"))
A12: צילום | B12: צילום רגעים - - שולם | D12: 11000 | E12: 4000 | F12: =IF(B12="","",MAX(0,D12-E12)) | G12: שולם חלקית | H12: =IF(B12="","",IF(C12="","כן","לא")) | I12: =IF(B12="","",IF(D12=0,"כן","לא")) | J12: =IF(B12="","",IF(F12>0,"כן","לא"))
A13: בר | B13: בר הבית | C13: 050-1112233 | D13: 18000 | E13: 0 | F13: =IF(B13="","",MAX(0,D13-E13)) | G13: פתוח לתשלום | H13: =IF(B13="","",IF(C13="","כן","לא")) | I13: =IF(B13="","",IF(D13=0,"כן","לא")) | J13: =IF(B13="","",IF(F13>0,"כן","לא"))
F14: =IF(B14="","",MAX(0,D14-E14)) | H14: =IF(B14="","",IF(C14="","כן","לא")) | I14: =IF(B14="","",IF(D14=0,"כן","לא")) | J14: =IF(B14="","",IF(F14>0,"כן","לא"))
F15: =IF(B15="","",MAX(0,D15-E15)) | H15: =IF(B15="","",IF(C15="","כן","לא")) | I15: =IF(B15="","",IF(D15=0,"כן","לא")) | J15: =IF(B15="","",IF(F15>0,"כן","לא"))
F16: =IF(B16="","",MAX(0,D16-E16)) | H16: =IF(B16="","",IF(C16="","כן","לא")) | I16: =IF(B16="","",IF(D16=0,"כן","לא")) | J16: =IF(B16="","",IF(F16>0,"כן","לא"))
F17: =IF(B17="","",MAX(0,D17-E17)) | H17: =IF(B17="","",IF(C17="","כן","לא")) | I17: =IF(B17="","",IF(D17=0,"כן","לא")) | J17: =IF(B17="","",IF(F17>0,"כן","לא"))
F18: =IF(B18="","",MAX(0,D18-E18)) | H18: =IF(B18="","",IF(C18="","כן","לא")) | I18: =IF(B18="","",IF(D18=0,"כן","לא")) | J18: =IF(B18="","",IF(F18>0,"כן","לא"))
F19: =IF(B19="","",MAX(0,D19-E19)) | H19: =IF(B19="","",IF(C19="","כן","לא")) | I19: =IF(B19="","",IF(D19=0,"כן","לא")) | J19: =IF(B19="","",IF(F19>0,"כן","לא"))
F20: =IF(B20="","",MAX(0,D20-E20)) | H20: =IF(B20="","",IF(C20="","כן","לא")) | I20: =IF(B20="","",IF(D20=0,"כן","לא")) | J20: =IF(B20="","",IF(F20>0,"כן","לא"))
F21: =IF(B21="","",MAX(0,D21-E21)) | H21: =IF(B21="","",IF(C21="","כן","לא")) | I21: =IF(B21="","",IF(D21=0,"כן","לא")) | J21: =IF(B21="","",IF(F21>0,"כן","לא"))
F22: =IF(B22="","",MAX(0,D22-E22)) | H22: =IF(B22="","",IF(C22="","כן","לא")) | I22: =IF(B22="","",IF(D22=0,"כן","לא")) | J22: =IF(B22="","",IF(F22>0,"כן","לא"))
F23: =IF(B23="","",MAX(0,D23-E23)) | H23: =IF(B23="","",IF(C23="","כן","לא")) | I23: =IF(B23="","",IF(D23=0,"כן","לא")) | J23: =IF(B23="","",IF(F23>0,"כן","לא"))
F24: =IF(B24="","",MAX(0,D24-E24)) | H24: =IF(B24="","",IF(C24="","כן","לא")) | I24: =IF(B24="","",IF(D24=0,"כן","לא")) | J24: =IF(B24="","",IF(F24>0,"כן","לא"))
F25: =IF(B25="","",MAX(0,D25-E25)) | H25: =IF(B25="","",IF(C25="","כן","לא")) | I25: =IF(B25="","",IF(D25=0,"כן","לא")) | J25: =IF(B25="","",IF(F25>0,"כן","לא"))
... F999: =IF(B999="","",MAX(0,D999-E999)) | H999: =IF(B999="","",IF(C999="","כן","לא")) | I999: =IF(B999="","",IF(D999=0,"כן","לא")) | J999: =IF(B999="","",IF(F999>0,"כן","לא"))

Sheet 08_Budget
A1: מדד | B1: ערך | C1: הערה
A2: עלות מתוכננת | B2: =B13 | C2: כולל ספקים וסעיפי תקציב
A3: עלות בפועל | B3: ='07_Suppliers'!B7 | C3: שולם לספקים
A4: עלות לאורח | B4: =IFERROR(B2/'01_סיכום_האירוע'!B6,0) | C4: מתעדכן לפי מוזמנים
A5: עלות לשולחן | B5: =IFERROR(B2/COUNTIF('05_Seating'!A14:A999,">0"),0) | C5: מתעדכן לפי שולחנות
A6: סעיף התקציב הגדול ביותר | B6: =IFERROR(INDEX(A11:A12,MATCH(MAX(B11:B12),B11:B12,0)),"") | C6: מדד תקציבי
A7: ניצול תקציב | B7: =IFERROR(B3/B2,0) | C7: שולם מתוך המתוכנן
A8: יתרה לתשלום | B8: ='07_Suppliers'!B8 | C8: דורש מעקב תשלום
A10: סעיף תקציב | B10: סכום | C10: הערות
A11: ספקים | B11: ='07_Suppliers'!B6 | C11: נמשך אוטומטית מגיליון ספקים
A12: אולם | B12: 65000 | C12: זוהה מטקסט חופשי
A13: סה״כ | B13: =SUM(B11:B12)

Sheet 09_Change_Impact
A1: שינוי | B1: השפעה | C1: החלטת מנהל
A2: שינוי כמות אורחים | B2: משפיע על קייטרינג, הושבה ותקציב | C2: לעדכון ידני
A3: שינוי ספק | B3: משפיע על תקציב ולוחות זמנים | C3: אישור מנהל אירוע
A4: סיכון חדש | B4: משפיע על בריף וניהול שטח | C4: תיעוד בגיליון סיכונים

Sheet 10_Risks
A1: סיכון | B1: כמות/מצב | C1: חומרה | D1: פעולה | E1: סטטוס | L1: ניווט לאפליקציה | M1: האקסל הוא ספר התכנון. הקישור פותח את תצוגת הסיכונים באפליקציה.
A2: אורחים ללא שולחן | B2: ='05_Seating'!B3 | C2: גבוהה | D2: לעדכן שולחן בגיליון אורחים/הושבה | E2: =IF(B2>0,"פעיל","תקין") | L2: פתח את תצוגת הסיכונים | M2: פתח את תצוגת הסיכונים
A3: שולחן מעל קיבולת | B3: ='05_Seating'!B8 | C3: גבוהה | D3: להקטין שיבוץ או להגדיל קיבולת | E3: =IF(B3>0,"פעיל","תקין")
A4: חסר טלפון ספק | B4: ='07_Suppliers'!B3 | C4: בינונית | D4: להשלים טלפון ספק | E4: =IF(B4>0,"פעיל","תקין")
A5: חסר עלות ספק | B5: ='07_Suppliers'!B4 | C5: בינונית | D5: להשלים עלות חוזה | E5: =IF(B5>0,"פעיל","תקין")
A6: ספקים לא משולמים | B6: ='07_Suppliers'!B5 | C6: בינונית | D6: לוודא סטטוס תשלום | E6: =IF(B6>0,"פעיל","תקין")
A7: חסר RSVP | B7: ='01_סיכום_האירוע'!B8 | C7: גבוהה | D7: לסגור אישורי הגעה ידנית | E7: =IF(B7>0,"פעיל","תקין")
A8: חריגת תקציב | B8: ='08_Budget'!B7 | C8: בינונית | D8: לבדוק ניצול תקציב | E8: =IF(B8>1,"פעיל","תקין")
A9: אלרגיה חמורה לאגוזים אצל אורח VIP | B9: 1 | C9: גבוהה | D9: בדיקה ואישור ידני לפני האירוע | E9: פעיל
A10: המלצת הושבה לבדיקה | B10: 1 | C10: נמוכה | D10: מומלץ להושיב את קבוצת 'חבר גרעין' בשולחן 1 — הקבוצה נכנסת במלואה. | E10: פעיל
A11: המלצת הושבה לבדיקה | B11: 1 | C11: נמוכה | D11: מומלץ להושיב את קבוצת 'לימודים' בשולחן 2 — הקבוצה נכנסת במלואה. | E11: פעיל
A12: המלצת הושבה לבדיקה | B12: 1 | C12: נמוכה | D12: מומלץ להושיב את קבוצת 'חבר גרעין, לימודים' בשולחן 3 — הקבוצה נכנסת במלואה. | E12: פעיל
A13: המלצת הושבה לבדיקה | B13: 1 | C13: נמוכה | D13: מומלץ להושיב את קבוצת 'משפחה' בשולחן 1 — הקבוצה נכנסת במלואה. | E13: פעיל
A14: המלצת הושבה לבדיקה | B14: 1 | C14: נמוכה | D14: קבוצת 'משפחה, VIP' כוללת 1 אורחים ולכן מומלץ לפצל בין שולחן 3. | E14: פעיל
A15: המלצת הושבה לבדיקה | B15: 1 | C15: נמוכה | D15: טרם השיבו — לא שובצו: לקוח: משפחת כהן-לוי | E15: פעיל
A16: המלצת הושבה לבדיקה | B16: 1 | C16: נמוכה | D16: המלצה בלבד — מנהל האירוע מחליט. | E16: פעיל

Sheet 11_Final_Brief
A1: בריף סופי | B1: ערך
A2: אורחים | B2: ="סה״כ "&'01_סיכום_האירוע'!B6&" אורחים; "&'01_סיכום_האירוע'!B7&" מאשרים; "&'01_סיכום_האירוע'!B8&" ממתינים"
A3: ספקים | B3: ="סה״כ ספקים: "&'01_סיכום_האירוע'!B18&"; יתרה לתשלום: "&TEXT('07_Suppliers'!B8,"₪#,##0")
A4: תקציב | B4: ="תקציב כולל: "&TEXT('08_Budget'!B2,"₪#,##0")&"; עלות לאורח: "&TEXT('08_Budget'!B4,"₪#,##0")
A5: הושבה | B5: ="תפוסת הושבה: "&TEXT('05_Seating'!B6,"0%")&"; ללא שולחן: "&'05_Seating'!B3
A6: סיכונים | B6: ="נושאים לטיפול: "&'01_סיכום_האירוע'!B23
A7: המלצות הושבה | B7: מומלץ להושיב את קבוצת 'חבר גרעין' בשולחן 1 — הקבוצה נכנסת במלואה. מומלץ להושיב את קבוצת 'לימודים' בשולחן 2 — הקבוצה נכנסת במלואה. מומלץ להושיב את קבוצת 'חבר גרעין, לימודים' בשולחן 3 — הקבוצה נכנסת במלואה. מומלץ להושיב את קבוצת 'משפחה' בשולחן 1 — הקבוצה נכנסת במלואה. קבוצת 'משפחה, VIP' כוללת 1 אורחים ולכן מומלץ לפצל בין שולחן 3. טרם השיבו — לא שובצו: לקוח: משפחת כהן-לוי המלצה בלבד — מנהל האירוע מחליט.
A8: הערת מקור אמת | B8: החוברת היא ספר התכנון התפעולי. האפליקציה משמשת לסקירה ויזואלית וניווט.

Sheet _EventSheet_Metadata
A1: שדה | B1: ערך
A2: eventId | B2: d2c1efcf-d570-4bfd-96af-56edded3d552
A3: eventName | B3: חתונת QA
A4: generatedAt | B4: 2026-06-09T15:39:53.973Z
A5: appOrigin | B5: http://127.0.0.1:5173
A6: workbookVersion | B6: 2.0-local-event-record
